<?xml version="1.0" encoding="utf-8"?>
<!-- This URDF was automatically created by SolidWorks to URDF Exporter! Originally created by Stephen Brawner (brawner@gmail.com) 
     Commit Version: 1.5.1-0-g916b5db  Build Version: 1.5.7152.31018
     For more information, please see http://wiki.ros.org/sw_urdf_exporter -->
<robot
  name="awjoint2080">
  <link
    name="rifJ20">
    <inertial>
      <origin
        xyz="0 0 -0.06758"
        rpy="0 0 0" />
      <mass
        value="3.87" />
      <inertia
        ixx="0.00670867"
        ixy="5.069E-05"
        ixz="-4.19E-05"
        iyy="0.010865"
        iyz="6.29E-06"
        izz="0.010458" />
    </inertial>
    <visual>
      <origin
        xyz="0 0 0"
        rpy="0 0 0" />
      <geometry>
        <mesh
          filename="package://awjoint2080/meshes/rifJ20.STL" />
      </geometry>
      <material
        name="">
        <color
          rgba="0.79216 0.81961 0.93333 1" />
      </material>
    </visual>
    <collision>
      <origin
        xyz="0 0 0"
        rpy="0 0 0" />
      <geometry>
        <mesh
          filename="package://awjoint2080/meshes/rifJ20.STL" />
      </geometry>
    </collision>
  </link>
  <link
    name="J20">
    <inertial>
      <origin
        xyz="0 0 -0.007"
        rpy="0 0 0" />
      <mass
        value="0.26" />
      <inertia
        ixx="0.000225"
        ixy="-5.2E-07"
        ixz="0"
        iyy="0.000225"
        iyz="0"
        izz="0.00042986" />
    </inertial>
    <visual>
      <origin
        xyz="0 0 0"
        rpy="0 0 0" />
      <geometry>
        <mesh
          filename="package://awjoint2080/meshes/J20.STL" />
      </geometry>
      <material
        name="">
        <color
          rgba="0.8902 0.8902 0.91373 1" />
      </material>
    </visual>
    <collision>
      <origin
        xyz="0 0 0"
        rpy="0 0 0" />
      <geometry>
        <mesh
          filename="package://awjoint2080/meshes/J20.STL" />
      </geometry>
    </collision>
  </link>
  <joint
    name="J20"
    type="revolute">
    <origin
      xyz="0.069 0 -0.069"
      rpy="0 1.5708 0" />
    <parent
      link="rifJ20" />
    <child
      link="J20" />
    <axis
      xyz="0 0 -1" />
    <limit
      lower="-3.14"
      upper="3.14"
      effort="80"
      velocity="3.61" />
    <dynamics
      damping="1"
      friction="0.1" />
  </joint>
</robot>