<?xml version="1.0" encoding="utf-8"?>
<!-- This URDF was automatically created by SolidWorks to URDF Exporter! Originally created by Stephen Brawner (brawner@gmail.com) 
     Commit Version: 1.5.1-0-g916b5db  Build Version: 1.5.7152.31018
     For more information, please see http://wiki.ros.org/sw_urdf_exporter -->
<robot
  name="awjoint32100">
  <link
    name="rifJ32">
    <inertial>
      <origin
        xyz="0 0 -0.1"
        rpy="0 0 0" />
      <mass
        value="13.18" />
      <inertia
        ixx="0.0697"
        ixy="-0.00012109"
        ixz="0"
        iyy="0.052615"
        iyz="6.171E-05"
        izz="0.067697" />
    </inertial>
    <visual>
      <origin
        xyz="0 0 0"
        rpy="0 0 0" />
      <geometry>
        <mesh
          filename="package://awjoint32100/meshes/rifJ32.STL" />
      </geometry>
      <material
        name="">
        <color
          rgba="0.79216 0.81961 0.93333 1" />
      </material>
    </visual>
    <collision>
      <origin
        xyz="0 0 0"
        rpy="0 0 0" />
      <geometry>
        <mesh
          filename="package://awjoint32100/meshes/rifJ32.STL" />
      </geometry>
    </collision>
  </link>
  <link
    name="J32">
    <inertial>
      <origin
        xyz="0 0 -0.01"
        rpy="0 0 0" />
      <mass
        value="0.99" />
      <inertia
        ixx="0.002116"
        ixy="0"
        ixz="0"
        iyy="0.002116"
        iyz="-2.8993E-20"
        izz="0.004099" />
    </inertial>
    <visual>
      <origin
        xyz="0 0 0"
        rpy="0 0 0" />
      <geometry>
        <mesh
          filename="package://awjoint32100/meshes/J32.STL" />
      </geometry>
      <material
        name="">
        <color
          rgba="0.8902 0.8902 0.91373 1" />
      </material>
    </visual>
    <collision>
      <origin
        xyz="0 0 0"
        rpy="0 0 0" />
      <geometry>
        <mesh
          filename="package://awjoint32100/meshes/J32.STL" />
      </geometry>
    </collision>
  </link>
  <joint
    name="J32"
    type="revolute">
    <origin
      xyz="0.1085 0 -0.1005"
      rpy="0 1.5708 0" />
    <parent
      link="rifJ32" />
    <child
      link="J32" />
    <axis
      xyz="0 0 -1" />
    <limit
      lower="-3.14"
      upper="3.14"
      effort="360"
      velocity="1.2436" />
    <dynamics
      damping="1"
      friction="0.1" />
  </joint>
</robot>