<?xml version="1.0" encoding="utf-8"?>
<!-- This URDF was automatically created by SolidWorks to URDF Exporter! Originally created by Stephen Brawner (brawner@gmail.com) 
     Commit Version: 1.5.1-0-g916b5db  Build Version: 1.5.7152.31018
     For more information, please see http://wiki.ros.org/sw_urdf_exporter -->
<robot
  name="awjoint40100">
  <link
    name="rifJ40">
    <inertial>
      <origin
        xyz="0 -0.017 -0.098"
        rpy="0 0 0" />
      <mass
        value="16.7" />
      <inertia
        ixx="0.094513"
        ixy="-0.000131"
        ixz="0"
        iyy="0.071007"
        iyz="0.0008105"
        izz="0.092453" />
    </inertial>
    <visual>
      <origin
        xyz="0 0 0"
        rpy="3.14 0 0" />
      <geometry>
        <mesh
          filename="package://awjoint40100/meshes/rifJ40.STL" />
      </geometry>
      <material
        name="">
        <color
          rgba="0.79216 0.81961 0.93333 1" />
      </material>
    </visual>
    <collision>
      <origin
        xyz="0 0 0"
        rpy="3.14 0 0" />
      <geometry>
        <mesh
          filename="package://awjoint40100/meshes/rifJ40.STL" />
      </geometry>
    </collision>
  </link>
  <link
    name="J40">
    <inertial>
      <origin
        xyz="0 0 -0.01385"
        rpy="0 0 0" />
      <mass
        value="1.17" />
      <inertia
        ixx="0.00303366"
        ixy="0"
        ixz="0"
        iyy="0.00303366"
        iyz="0"
        izz="0.00584945" />
    </inertial>
    <visual>
      <origin
        xyz="0 0 0"
        rpy="0 0 0" />
      <geometry>
        <mesh
          filename="package://awjoint40100/meshes/J40.STL" />
      </geometry>
      <material
        name="">
        <color
          rgba="0.8902 0.8902 0.91373 1" />
      </material>
    </visual>
    <collision>
      <origin
        xyz="0 0 0"
        rpy="0 0 0" />
      <geometry>
        <mesh
          filename="package://awjoint40100/meshes/J40.STL" />
      </geometry>
    </collision>
  </link>
  <joint
    name="J40"
    type="revolute">
    <origin
      xyz="0.1179 0 +0.1045"
      rpy="0 1.5708 0" />
    <parent
      link="rifJ40" />
    <child
      link="J40" />
    <axis
      xyz="0 0 -1" />
    <limit
      lower="-3.14"
      upper="3.14"
      effort="630"
      velocity="1.24" />
    <dynamics
      damping="1"
      friction="0.1" />
  </joint>
</robot>