<?xml version="1.0" encoding="utf-8"?>
<!-- This URDF was automatically created by SolidWorks to URDF Exporter! Originally created by Stephen Brawner (brawner@gmail.com) 
     Commit Version: 1.5.1-0-g916b5db  Build Version: 1.5.7152.31018
     For more information, please see http://wiki.ros.org/sw_urdf_exporter -->
<robot
  name="awjoint1750">
  <link
    name="rifJ17">
    <inertial>
      <origin
        xyz="-0.01362 0 -0.070101"
        rpy="0 0 0" />
      <mass
        value="2.9" />
      <inertia
        ixx="0.0054767"
        ixy="1.963E-05"
        ixz="0.00015375"
        iyy="0.008238"
        iyz="0"
        izz="0.0076285" />
    </inertial>
    <visual>
      <origin
        xyz="0 0 0"
        rpy="3.14 0 0" />
      <geometry>
        <mesh
          filename="package://awjoint1750/meshes/rifJ17.STL" />
      </geometry>
      <material
        name="">
        <color
          rgba="0.79216 0.81961 0.93333 1" />
      </material>
    </visual>
    <collision>
      <origin
        xyz="0 0 0"
        rpy="3.14 0 0" />
      <geometry>
        <mesh
          filename="package://awjoint1750/meshes/rifJ17.STL" />
      </geometry>
    </collision>
  </link>
  <link
    name="J17">
    <inertial>
      <origin
        xyz="0 0 -0.0108"
        rpy="0 0 0" />
      <mass
        value="0.35" />
      <inertia
        ixx="0.00026398"
        ixy="0"
        ixz="0"
        iyy="0.00026449"
        iyz="0"
        izz="0.00049327" />
    </inertial>
    <visual>
      <origin
        xyz="0 0 0"
        rpy="0 0 0" />
      <geometry>
        <mesh
          filename="package://awjoint1750/meshes/J17.STL" />
      </geometry>
      <material
        name="">
        <color
          rgba="0.8902 0.8902 0.91373 1" />
      </material>
    </visual>
    <collision>
      <origin
        xyz="0 0 0"
        rpy="0 0 0" />
      <geometry>
        <mesh
          filename="package://awjoint1750/meshes/J17.STL" />
      </geometry>
    </collision>
  </link>
  <joint
    name="J17"
    type="revolute">
    <origin
      xyz="0.08 0 +0.076"
      rpy="0 1.5708 0" />
    <parent
      link="rifJ17" />
    <child
      link="J17" />
    <axis
      xyz="0 0 -1" />
    <limit
      lower="-3.14"
      upper="3.14"
      effort="37"
      velocity="6.36" />
    <dynamics
      damping="1"
      friction="0.1" />
  </joint>
</robot>